cd /home/phage/codev/SafetyVault ; /usr/bin/env /bin/python3 /home/phage/.vscode/extensions/ms-python.debugpy-2024.12.0-linux-x64/bundled/libs
/debugpy/adapter/../../debugpy/launcher 59617 -- /home/phage/codev/SafetyVault/pico-vault/vault.py 
Connecting to hardware wallet...
Challenge sent
Traceback (most recent call last):
  File "/usr/lib/python3/dist-packages/serial/serialposix.py", line 621, in write
    n = os.write(self.fd, d)
        ^^^^^^^^^^^^^^^^^^^^
OSError: [Errno 5] Input/output error

During handling of the above exception, another exception occurred:

Traceback (most recent call last):
  File "/usr/lib/python3.11/runpy.py", line 198, in _run_module_as_main
    return _run_code(code, main_globals, None,
           ^^^^^^^^^^^^^^^^^^^^^^^^^^^^^^^^^^^
  File "/usr/lib/python3.11/runpy.py", line 88, in _run_code
    exec(code, run_globals)
  File "/home/phage/.vscode/extensions/ms-python.debugpy-2024.12.0-linux-x64/bundled/libs/debugpy/adapter/../../debugpy/launcher/../../debugpy/__main__.py", line 71, in <module>
    cli.main()
  File "/home/phage/.vscode/extensions/ms-python.debugpy-2024.12.0-linux-x64/bundled/libs/debugpy/adapter/../../debugpy/launcher/../../debugpy/../debugpy/server/cli.py", line 501, in main
    run()
  File "/home/phage/.vscode/extensions/ms-python.debugpy-2024.12.0-linux-x64/bundled/libs/debugpy/adapter/../../debugpy/launcher/../../debugpy/../debugpy/server/cli.py", line 351, in run_file
    runpy.run_path(target, run_name="__main__")
  File "/home/phage/.vscode/extensions/ms-python.debugpy-2024.12.0-linux-x64/bundled/libs/debugpy/_vendored/pydevd/_pydevd_bundle/pydevd_runpy.py", line 310, in run_path
    return _run_module_code(code, init_globals, run_name, pkg_name=pkg_name, script_name=fname)
           ^^^^^^^^^^^^^^^^^^^^^^^^^^^^^^^^^^^^^^^^^^^^^^^^^^^^^^^^^^^^^^^^^^^^^^^^^^^^^^^^^^^^
  File "/home/phage/.vscode/extensions/ms-python.debugpy-2024.12.0-linux-x64/bundled/libs/debugpy/_vendored/pydevd/_pydevd_bundle/pydevd_runpy.py", line 127, in _run_module_code
    _run_code(code, mod_globals, init_globals, mod_name, mod_spec, pkg_name, script_name)
  File "/home/phage/.vscode/extensions/ms-python.debugpy-2024.12.0-linux-x64/bundled/libs/debugpy/_vendored/pydevd/_pydevd_bundle/pydevd_runpy.py", line 118, in _run_code
    exec(code, run_globals)
  File "/home/phage/codev/SafetyVault/pico-vault/vault.py", line 105, in <module>
    checkresult = first_key_verify()
                  ^^^^^^^^^^^^^^^^^^
  File "/home/phage/codev/SafetyVault/pico-vault/vault.py", line 49, in first_key_verify
    ser.write(challenge)
  File "/usr/lib/python3/dist-packages/serial/serialposix.py", line 655, in write
    raise SerialException('write failed: {}'.format(e))
serial.serialutil.SerialException: write failed: [Errno 5] Input/output error